module Celluloid
  # Calls represent requests to an actor
  class Call
    attr_reader :id, :caller, :method, :arguments, :block

    def initialize(caller, method, arguments, block)
      @id = object_id # memoize object ID for serialization
      @caller, @method, @arguments, @block = caller, method, arguments, block
    end

    def check_signature(obj)
      unless obj.respond_to? @method
        raise NoMethodError, "undefined method `#{@method}' for #{obj.inspect}"
      end

      arity = obj.method(@method).arity
      if arity >= 0
        if arguments.size != arity
          raise ArgumentError, "wrong number of arguments (#{arguments.size} for #{arity})"
        end
      elsif arity < -1
        mandatory_args = -arity - 1
        if arguments.size < mandatory_args
          raise ArgumentError, "wrong number of arguments (#{arguments.size} for #{mandatory_args})"
        end
      end
    end
  end

  # Synchronous calls wait for a response
  class SyncCall < Call
    def dispatch(obj)
      begin
        check_signature(obj)
      rescue Exception => ex
        respond ErrorResponse.new(@id, AbortError.new(ex))
        return
      end

      begin
        result = obj.send @method, *@arguments, &@block
      rescue Exception => exception
        # Exceptions that occur during synchronous calls are reraised in the
        # context of the caller
        respond ErrorResponse.new(@id, exception)

        if exception.is_a? AbortError
          # Aborting indicates a protocol error on the part of the caller
          # It should crash the caller, but the exception isn't reraised
          return
        else
          # Otherwise, it's a bug in this actor and should be reraised
          raise exception
        end
      end

      respond SuccessResponse.new(@id, result)
    end

    def cleanup
      exception = DeadActorError.new("attempted to call a dead actor")
      respond ErrorResponse.new(@id, exception)
    end

    #######
    private
    #######

    def respond(message)
      @caller << message
    rescue MailboxError
      # It's possible the caller exited or crashed before we could send a
      # response to them.
    end
  end

  # Asynchronous calls don't wait for a response
  class AsyncCall < Call
    def dispatch(obj)
      begin
        check_signature(obj)
      rescue Exception => ex
        Logger.crash("#{obj.class}: async call failed!", ex)
        return
      end

      obj.send(@method, *@arguments, &@block)
    rescue AbortError => ex
      # Swallow aborted async calls, as they indicate the caller made a mistake
      Logger.crash("#{obj.class}: async call aborted!", ex)
    end
  end
end

